Workbook
Name Classes: 'Lists'!$A$5:$A$44

Sheet Dashboard
A1: INSTRUCTOR HOURS | FISCAL YEAR DASHBOARD
A2: Federal fiscal year: October 1 through September 30 | Change the FY in B4.
A4: SELECT FISCAL YEAR | B4: 2027 | C4: FY 2027 = Oct 1, 2026 - Sep 30, 2027
A6: CONTACT HOURS | C6: PRODUCTION HOURS | E6: CONSULTATION HOURS
A7: =SUM(B36:B47) -> 0 | C7: =SUM(C36:C47) -> 0 | E7: =SUM(D36:D47) -> 0
A10: ALL INSTRUCTOR HOURS
A11: =SUM(E36:E47) -> 0
A14: FY BEGINS | C14: FY ENDS | E14: YEAR ELAPSED
A15: =DATE(B4-1,10,1) -> 0 | C15: =DATE(B4,9,30) -> 0 | E15: =IF(TODAY()<DATE(B4-1,10,1),0,IF(TODAY()>DATE(B4,9,30),1,(TODAY()-DATE(B4-1,10,1)+1)/(DATE(B4,10,1)-DATE(B4-1,10,1)))) -> 0
A19: FISCAL YEAR PROGRESS
A20: =IF(TODAY()<DATE(B4-1,10,1),"Not started",IF(TODAY()>DATE(B4,9,30),"Completed","In progress: "&TEXT(E15,"0.0%"))) -> 0
A26: TRACK HOURS BY ACTIVITY
A27: Enter dated activities in Hours Log. The dashboard updates from the selected FY.
A33: MONTHLY HOURS - OCTOBER THROUGH SEPTEMBER
A35: MONTH | B35: CONTACT | C35: PRODUCTION | D35: CONSULTATION | E35: TOTAL | F35: MONTH TRACKER
A36: =DATE(B4-1,10,1) -> 0 | B36: =SUMIFS('Hours Log'!$D$5:$D$504,'Hours Log'!$B$5:$B$504,">="&$A36,'Hours Log'!$B$5:$B$504,"<"&EDATE(A36,1)) -> 0 | C36: =SUMIFS('Hours Log'!$E$5:$E$504,'Hours Log'!$B$5:$B$504,">="&$A36,'Hours Log'!$B$5:$B$504,"<"&EDATE(A36,1)) -> 0 | D36: =SUMIFS('Hours Log'!$F$5:$F$504,'Hours Log'!$B$5:$B$504,">="&$A36,'Hours Log'!$B$5:$B$504,"<"&EDATE(A36,1)) -> 0 | E36: =SUM(B36:D36) -> 0 | F36: =IF(TODAY()<A36,0,IF(TODAY()>=EDATE(A36,1),1,(TODAY()-A36+1)/(EDATE(A36,1)-A36))) -> 0
A37: =DATE(B4-1,11,1) -> 0 | B37: =SUMIFS('Hours Log'!$D$5:$D$504,'Hours Log'!$B$5:$B$504,">="&$A37,'Hours Log'!$B$5:$B$504,"<"&EDATE(A37,1)) -> 0 | C37: =SUMIFS('Hours Log'!$E$5:$E$504,'Hours Log'!$B$5:$B$504,">="&$A37,'Hours Log'!$B$5:$B$504,"<"&EDATE(A37,1)) -> 0 | D37: =SUMIFS('Hours Log'!$F$5:$F$504,'Hours Log'!$B$5:$B$504,">="&$A37,'Hours Log'!$B$5:$B$504,"<"&EDATE(A37,1)) -> 0 | E37: =SUM(B37:D37) -> 0 | F37: =IF(TODAY()<A37,0,IF(TODAY()>=EDATE(A37,1),1,(TODAY()-A37+1)/(EDATE(A37,1)-A37))) -> 0
A38: =DATE(B4-1,12,1) -> 0 | B38: =SUMIFS('Hours Log'!$D$5:$D$504,'Hours Log'!$B$5:$B$504,">="&$A38,'Hours Log'!$B$5:$B$504,"<"&EDATE(A38,1)) -> 0 | C38: =SUMIFS('Hours Log'!$E$5:$E$504,'Hours Log'!$B$5:$B$504,">="&$A38,'Hours Log'!$B$5:$B$504,"<"&EDATE(A38,1)) -> 0 | D38: =SUMIFS('Hours Log'!$F$5:$F$504,'Hours Log'!$B$5:$B$504,">="&$A38,'Hours Log'!$B$5:$B$504,"<"&EDATE(A38,1)) -> 0 | E38: =SUM(B38:D38) -> 0 | F38: =IF(TODAY()<A38,0,IF(TODAY()>=EDATE(A38,1),1,(TODAY()-A38+1)/(EDATE(A38,1)-A38))) -> 0
A39: =DATE(B4,1,1) -> 0 | B39: =SUMIFS('Hours Log'!$D$5:$D$504,'Hours Log'!$B$5:$B$504,">="&$A39,'Hours Log'!$B$5:$B$504,"<"&EDATE(A39,1)) -> 0 | C39: =SUMIFS('Hours Log'!$E$5:$E$504,'Hours Log'!$B$5:$B$504,">="&$A39,'Hours Log'!$B$5:$B$504,"<"&EDATE(A39,1)) -> 0 | D39: =SUMIFS('Hours Log'!$F$5:$F$504,'Hours Log'!$B$5:$B$504,">="&$A39,'Hours Log'!$B$5:$B$504,"<"&EDATE(A39,1)) -> 0 | E39: =SUM(B39:D39) -> 0 | F39: =IF(TODAY()<A39,0,IF(TODAY()>=EDATE(A39,1),1,(TODAY()-A39+1)/(EDATE(A39,1)-A39))) -> 0
A40: =DATE(B4,2,1) -> 0 | B40: =SUMIFS('Hours Log'!$D$5:$D$504,'Hours Log'!$B$5:$B$504,">="&$A40,'Hours Log'!$B$5:$B$504,"<"&EDATE(A40,1)) -> 0 | C40: =SUMIFS('Hours Log'!$E$5:$E$504,'Hours Log'!$B$5:$B$504,">="&$A40,'Hours Log'!$B$5:$B$504,"<"&EDATE(A40,1)) -> 0 | D40: =SUMIFS('Hours Log'!$F$5:$F$504,'Hours Log'!$B$5:$B$504,">="&$A40,'Hours Log'!$B$5:$B$504,"<"&EDATE(A40,1)) -> 0 | E40: =SUM(B40:D40) -> 0 | F40: =IF(TODAY()<A40,0,IF(TODAY()>=EDATE(A40,1),1,(TODAY()-A40+1)/(EDATE(A40,1)-A40))) -> 0
A41: =DATE(B4,3,1) -> 0 | B41: =SUMIFS('Hours Log'!$D$5:$D$504,'Hours Log'!$B$5:$B$504,">="&$A41,'Hours Log'!$B$5:$B$504,"<"&EDATE(A41,1)) -> 0 | C41: =SUMIFS('Hours Log'!$E$5:$E$504,'Hours Log'!$B$5:$B$504,">="&$A41,'Hours Log'!$B$5:$B$504,"<"&EDATE(A41,1)) -> 0 | D41: =SUMIFS('Hours Log'!$F$5:$F$504,'Hours Log'!$B$5:$B$504,">="&$A41,'Hours Log'!$B$5:$B$504,"<"&EDATE(A41,1)) -> 0 | E41: =SUM(B41:D41) -> 0 | F41: =IF(TODAY()<A41,0,IF(TODAY()>=EDATE(A41,1),1,(TODAY()-A41+1)/(EDATE(A41,1)-A41))) -> 0
A42: =DATE(B4,4,1) -> 0 | B42: =SUMIFS('Hours Log'!$D$5:$D$504,'Hours Log'!$B$5:$B$504,">="&$A42,'Hours Log'!$B$5:$B$504,"<"&EDATE(A42,1)) -> 0 | C42: =SUMIFS('Hours Log'!$E$5:$E$504,'Hours Log'!$B$5:$B$504,">="&$A42,'Hours Log'!$B$5:$B$504,"<"&EDATE(A42,1)) -> 0 | D42: =SUMIFS('Hours Log'!$F$5:$F$504,'Hours Log'!$B$5:$B$504,">="&$A42,'Hours Log'!$B$5:$B$504,"<"&EDATE(A42,1)) -> 0 | E42: =SUM(B42:D42) -> 0 | F42: =IF(TODAY()<A42,0,IF(TODAY()>=EDATE(A42,1),1,(TODAY()-A42+1)/(EDATE(A42,1)-A42))) -> 0
A43: =DATE(B4,5,1) -> 0 | B43: =SUMIFS('Hours Log'!$D$5:$D$504,'Hours Log'!$B$5:$B$504,">="&$A43,'Hours Log'!$B$5:$B$504,"<"&EDATE(A43,1)) -> 0 | C43: =SUMIFS('Hours Log'!$E$5:$E$504,'Hours Log'!$B$5:$B$504,">="&$A43,'Hours Log'!$B$5:$B$504,"<"&EDATE(A43,1)) -> 0 | D43: =SUMIFS('Hours Log'!$F$5:$F$504,'Hours Log'!$B$5:$B$504,">="&$A43,'Hours Log'!$B$5:$B$504,"<"&EDATE(A43,1)) -> 0 | E43: =SUM(B43:D43) -> 0 | F43: =IF(TODAY()<A43,0,IF(TODAY()>=EDATE(A43,1),1,(TODAY()-A43+1)/(EDATE(A43,1)-A43))) -> 0
A44: =DATE(B4,6,1) -> 0 | B44: =SUMIFS('Hours Log'!$D$5:$D$504,'Hours Log'!$B$5:$B$504,">="&$A44,'Hours Log'!$B$5:$B$504,"<"&EDATE(A44,1)) -> 0 | C44: =SUMIFS('Hours Log'!$E$5:$E$504,'Hours Log'!$B$5:$B$504,">="&$A44,'Hours Log'!$B$5:$B$504,"<"&EDATE(A44,1)) -> 0 | D44: =SUMIFS('Hours Log'!$F$5:$F$504,'Hours Log'!$B$5:$B$504,">="&$A44,'Hours Log'!$B$5:$B$504,"<"&EDATE(A44,1)) -> 0 | E44: =SUM(B44:D44) -> 0 | F44: =IF(TODAY()<A44,0,IF(TODAY()>=EDATE(A44,1),1,(TODAY()-A44+1)/(EDATE(A44,1)-A44))) -> 0
A45: =DATE(B4,7,1) -> 0 | B45: =SUMIFS('Hours Log'!$D$5:$D$504,'Hours Log'!$B$5:$B$504,">="&$A45,'Hours Log'!$B$5:$B$504,"<"&EDATE(A45,1)) -> 0 | C45: =SUMIFS('Hours Log'!$E$5:$E$504,'Hours Log'!$B$5:$B$504,">="&$A45,'Hours Log'!$B$5:$B$504,"<"&EDATE(A45,1)) -> 0 | D45: =SUMIFS('Hours Log'!$F$5:$F$504,'Hours Log'!$B$5:$B$504,">="&$A45,'Hours Log'!$B$5:$B$504,"<"&EDATE(A45,1)) -> 0 | E45: =SUM(B45:D45) -> 0 | F45: =IF(TODAY()<A45,0,IF(TODAY()>=EDATE(A45,1),1,(TODAY()-A45+1)/(EDATE(A45,1)-A45))) -> 0
A46: =DATE(B4,8,1) -> 0 | B46: =SUMIFS('Hours Log'!$D$5:$D$504,'Hours Log'!$B$5:$B$504,">="&$A46,'Hours Log'!$B$5:$B$504,"<"&EDATE(A46,1)) -> 0 | C46: =SUMIFS('Hours Log'!$E$5:$E$504,'Hours Log'!$B$5:$B$504,">="&$A46,'Hours Log'!$B$5:$B$504,"<"&EDATE(A46,1)) -> 0 | D46: =SUMIFS('Hours Log'!$F$5:$F$504,'Hours Log'!$B$5:$B$504,">="&$A46,'Hours Log'!$B$5:$B$504,"<"&EDATE(A46,1)) -> 0 | E46: =SUM(B46:D46) -> 0 | F46: =IF(TODAY()<A46,0,IF(TODAY()>=EDATE(A46,1),1,(TODAY()-A46+1)/(EDATE(A46,1)-A46))) -> 0
A47: =DATE(B4,9,1) -> 0 | B47: =SUMIFS('Hours Log'!$D$5:$D$504,'Hours Log'!$B$5:$B$504,">="&$A47,'Hours Log'!$B$5:$B$504,"<"&EDATE(A47,1)) -> 0 | C47: =SUMIFS('Hours Log'!$E$5:$E$504,'Hours Log'!$B$5:$B$504,">="&$A47,'Hours Log'!$B$5:$B$504,"<"&EDATE(A47,1)) -> 0 | D47: =SUMIFS('Hours Log'!$F$5:$F$504,'Hours Log'!$B$5:$B$504,">="&$A47,'Hours Log'!$B$5:$B$504,"<"&EDATE(A47,1)) -> 0 | E47: =SUM(B47:D47) -> 0 | F47: =IF(TODAY()<A47,0,IF(TODAY()>=EDATE(A47,1),1,(TODAY()-A47+1)/(EDATE(A47,1)-A47))) -> 0
A48: FISCAL TOTAL | B48: =SUM(B36:B47) -> 0 | C48: =SUM(C36:C47) -> 0 | D48: =SUM(D36:D47) -> 0 | E48: =SUM(E36:E47) -> 0 | F48: =E15 -> 0
A50: FY 2027 includes Oct-Dec 2026 and Jan-Sep 2027; changing B4 selects any FY.
Q13: Contact Hours | R13: =A7 -> 0
Q14: Production Hours | R14: =C7 -> 0
Q15: Consultation Hours | R15: =E7 -> 0
Q36: Oct
Q37: Nov
Q38: Dec
Q39: Jan
Q40: Feb
Q41: Mar
Q42: Apr
Q43: May
...

Sheet Hours Log
A1: INSTRUCTOR HOURS LOG
A2: Add one row per activity; enter dates and hours. Fiscal year, month, year and totals calculate automatically.
A4: ENTRY # | B4: DATE | C4: CLASS | D4: CONTACT HOURS | E4: PRODUCTION HOURS | F4: CONSULTATION HOURS | G4: TOTAL HOURS | H4: MONTH | I4: YEAR | J4: NOTES | K4: FISCAL YEAR
A5: 1 | G5: =IF(B5="","",SUM(D5:F5)) -> 0 | H5: =IF(B5="","",TEXT(B5,"mmm")) -> 0 | I5: =IF(B5="","",YEAR(B5)) -> 0 | K5: =IF(B5="","",YEAR(B5)+IF(MONTH(B5)>=10,1,0)) -> 0
A6: 2 | G6: =IF(B6="","",SUM(D6:F6)) -> 0 | H6: =IF(B6="","",TEXT(B6,"mmm")) -> 0 | I6: =IF(B6="","",YEAR(B6)) -> 0 | K6: =IF(B6="","",YEAR(B6)+IF(MONTH(B6)>=10,1,0)) -> 0
A7: 3 | G7: =IF(B7="","",SUM(D7:F7)) -> 0 | H7: =IF(B7="","",TEXT(B7,"mmm")) -> 0 | I7: =IF(B7="","",YEAR(B7)) -> 0 | K7: =IF(B7="","",YEAR(B7)+IF(MONTH(B7)>=10,1,0)) -> 0
A8: 4 | G8: =IF(B8="","",SUM(D8:F8)) -> 0 | H8: =IF(B8="","",TEXT(B8,"mmm")) -> 0 | I8: =IF(B8="","",YEAR(B8)) -> 0 | K8: =IF(B8="","",YEAR(B8)+IF(MONTH(B8)>=10,1,0)) -> 0
A9: 5 | G9: =IF(B9="","",SUM(D9:F9)) -> 0 | H9: =IF(B9="","",TEXT(B9,"mmm")) -> 0 | I9: =IF(B9="","",YEAR(B9)) -> 0 | K9: =IF(B9="","",YEAR(B9)+IF(MONTH(B9)>=10,1,0)) -> 0
A10: 6 | G10: =IF(B10="","",SUM(D10:F10)) -> 0 | H10: =IF(B10="","",TEXT(B10,"mmm")) -> 0 | I10: =IF(B10="","",YEAR(B10)) -> 0 | K10: =IF(B10="","",YEAR(B10)+IF(MONTH(B10)>=10,1,0)) -> 0
A11: 7 | G11: =IF(B11="","",SUM(D11:F11)) -> 0 | H11: =IF(B11="","",TEXT(B11,"mmm")) -> 0 | I11: =IF(B11="","",YEAR(B11)) -> 0 | K11: =IF(B11="","",YEAR(B11)+IF(MONTH(B11)>=10,1,0)) -> 0
A12: 8 | G12: =IF(B12="","",SUM(D12:F12)) -> 0 | H12: =IF(B12="","",TEXT(B12,"mmm")) -> 0 | I12: =IF(B12="","",YEAR(B12)) -> 0 | K12: =IF(B12="","",YEAR(B12)+IF(MONTH(B12)>=10,1,0)) -> 0
A13: 9 | G13: =IF(B13="","",SUM(D13:F13)) -> 0 | H13: =IF(B13="","",TEXT(B13,"mmm")) -> 0 | I13: =IF(B13="","",YEAR(B13)) -> 0 | K13: =IF(B13="","",YEAR(B13)+IF(MONTH(B13)>=10,1,0)) -> 0
A14: 10 | G14: =IF(B14="","",SUM(D14:F14)) -> 0 | H14: =IF(B14="","",TEXT(B14,"mmm")) -> 0 | I14: =IF(B14="","",YEAR(B14)) -> 0 | K14: =IF(B14="","",YEAR(B14)+IF(MONTH(B14)>=10,1,0)) -> 0
A15: 11 | G15: =IF(B15="","",SUM(D15:F15)) -> 0 | H15: =IF(B15="","",TEXT(B15,"mmm")) -> 0 | I15: =IF(B15="","",YEAR(B15)) -> 0 | K15: =IF(B15="","",YEAR(B15)+IF(MONTH(B15)>=10,1,0)) -> 0
A16: 12 | G16: =IF(B16="","",SUM(D16:F16)) -> 0 | H16: =IF(B16="","",TEXT(B16,"mmm")) -> 0 | I16: =IF(B16="","",YEAR(B16)) -> 0 | K16: =IF(B16="","",YEAR(B16)+IF(MONTH(B16)>=10,1,0)) -> 0
... A504: 500 | G504: =IF(B504="","",SUM(D504:F504)) -> 0 | H504: =IF(B504="","",TEXT(B504,"mmm")) -> 0 | I504: =IF(B504="","",YEAR(B504)) -> 0 | K504: =IF(B504="","",YEAR(B504)+IF(MONTH(B504)>=10,1,0)) -> 0

Sheet Class Summary
A1: CLASS HOURS SUMMARY
A2: All class totals are calculated for the fiscal year selected on the Dashboard.
A4: CLASS | B4: CONTACT HOURS | C4: PRODUCTION HOURS | D4: CONSULTATION HOURS | E4: TOTAL HOURS
A5: =Lists!A5 -> 0 | B5: =SUMIFS('Hours Log'!$D$5:$D$504,'Hours Log'!$C$5:$C$504,$A5,'Hours Log'!$B$5:$B$504,">="&DATE(Dashboard!$B$4-1,10,1),'Hours Log'!$B$5:$B$504,"<"&DATE(Dashboard!$B$4,10,1)) -> 0 | C5: =SUMIFS('Hours Log'!$E$5:$E$504,'Hours Log'!$C$5:$C$504,$A5,'Hours Log'!$B$5:$B$504,">="&DATE(Dashboard!$B$4-1,10,1),'Hours Log'!$B$5:$B$504,"<"&DATE(Dashboard!$B$4,10,1)) -> 0 | D5: =SUMIFS('Hours Log'!$F$5:$F$504,'Hours Log'!$C$5:$C$504,$A5,'Hours Log'!$B$5:$B$504,">="&DATE(Dashboard!$B$4-1,10,1),'Hours Log'!$B$5:$B$504,"<"&DATE(Dashboard!$B$4,10,1)) -> 0 | E5: =SUM(B5:D5) -> 0
A6: =Lists!A6 -> 0 | B6: =SUMIFS('Hours Log'!$D$5:$D$504,'Hours Log'!$C$5:$C$504,$A6,'Hours Log'!$B$5:$B$504,">="&DATE(Dashboard!$B$4-1,10,1),'Hours Log'!$B$5:$B$504,"<"&DATE(Dashboard!$B$4,10,1)) -> 0 | C6: =SUMIFS('Hours Log'!$E$5:$E$504,'Hours Log'!$C$5:$C$504,$A6,'Hours Log'!$B$5:$B$504,">="&DATE(Dashboard!$B$4-1,10,1),'Hours Log'!$B$5:$B$504,"<"&DATE(Dashboard!$B$4,10,1)) -> 0 | D6: =SUMIFS('Hours Log'!$F$5:$F$504,'Hours Log'!$C$5:$C$504,$A6,'Hours Log'!$B$5:$B$504,">="&DATE(Dashboard!$B$4-1,10,1),'Hours Log'!$B$5:$B$504,"<"&DATE(Dashboard!$B$4,10,1)) -> 0 | E6: =SUM(B6:D6) -> 0
A7: =Lists!A7 -> 0 | B7: =SUMIFS('Hours Log'!$D$5:$D$504,'Hours Log'!$C$5:$C$504,$A7,'Hours Log'!$B$5:$B$504,">="&DATE(Dashboard!$B$4-1,10,1),'Hours Log'!$B$5:$B$504,"<"&DATE(Dashboard!$B$4,10,1)) -> 0 | C7: =SUMIFS('Hours Log'!$E$5:$E$504,'Hours Log'!$C$5:$C$504,$A7,'Hours Log'!$B$5:$B$504,">="&DATE(Dashboard!$B$4-1,10,1),'Hours Log'!$B$5:$B$504,"<"&DATE(Dashboard!$B$4,10,1)) -> 0 | D7: =SUMIFS('Hours Log'!$F$5:$F$504,'Hours Log'!$C$5:$C$504,$A7,'Hours Log'!$B$5:$B$504,">="&DATE(Dashboard!$B$4-1,10,1),'Hours Log'!$B$5:$B$504,"<"&DATE(Dashboard!$B$4,10,1)) -> 0 | E7: =SUM(B7:D7) -> 0
A8: =Lists!A8 -> 0 | B8: =SUMIFS('Hours Log'!$D$5:$D$504,'Hours Log'!$C$5:$C$504,$A8,'Hours Log'!$B$5:$B$504,">="&DATE(Dashboard!$B$4-1,10,1),'Hours Log'!$B$5:$B$504,"<"&DATE(Dashboard!$B$4,10,1)) -> 0 | C8: =SUMIFS('Hours Log'!$E$5:$E$504,'Hours Log'!$C$5:$C$504,$A8,'Hours Log'!$B$5:$B$504,">="&DATE(Dashboard!$B$4-1,10,1),'Hours Log'!$B$5:$B$504,"<"&DATE(Dashboard!$B$4,10,1)) -> 0 | D8: =SUMIFS('Hours Log'!$F$5:$F$504,'Hours Log'!$C$5:$C$504,$A8,'Hours Log'!$B$5:$B$504,">="&DATE(Dashboard!$B$4-1,10,1),'Hours Log'!$B$5:$B$504,"<"&DATE(Dashboard!$B$4,10,1)) -> 0 | E8: =SUM(B8:D8) -> 0
A9: =Lists!A9 -> 0 | B9: =SUMIFS('Hours Log'!$D$5:$D$504,'Hours Log'!$C$5:$C$504,$A9,'Hours Log'!$B$5:$B$504,">="&DATE(Dashboard!$B$4-1,10,1),'Hours Log'!$B$5:$B$504,"<"&DATE(Dashboard!$B$4,10,1)) -> 0 | C9: =SUMIFS('Hours Log'!$E$5:$E$504,'Hours Log'!$C$5:$C$504,$A9,'Hours Log'!$B$5:$B$504,">="&DATE(Dashboard!$B$4-1,10,1),'Hours Log'!$B$5:$B$504,"<"&DATE(Dashboard!$B$4,10,1)) -> 0 | D9: =SUMIFS('Hours Log'!$F$5:$F$504,'Hours Log'!$C$5:$C$504,$A9,'Hours Log'!$B$5:$B$504,">="&DATE(Dashboard!$B$4-1,10,1),'Hours Log'!$B$5:$B$504,"<"&DATE(Dashboard!$B$4,10,1)) -> 0 | E9: =SUM(B9:D9) -> 0
A10: =Lists!A10 -> 0 | B10: =SUMIFS('Hours Log'!$D$5:$D$504,'Hours Log'!$C$5:$C$504,$A10,'Hours Log'!$B$5:$B$504,">="&DATE(Dashboard!$B$4-1,10,1),'Hours Log'!$B$5:$B$504,"<"&DATE(Dashboard!$B$4,10,1)) -> 0 | C10: =SUMIFS('Hours Log'!$E$5:$E$504,'Hours Log'!$C$5:$C$504,$A10,'Hours Log'!$B$5:$B$504,">="&DATE(Dashboard!$B$4-1,10,1),'Hours Log'!$B$5:$B$504,"<"&DATE(Dashboard!$B$4,10,1)) -> 0 | D10: =SUMIFS('Hours Log'!$F$5:$F$504,'Hours Log'!$C$5:$C$504,$A10,'Hours Log'!$B$5:$B$504,">="&DATE(Dashboard!$B$4-1,10,1),'Hours Log'!$B$5:$B$504,"<"&DATE(Dashboard!$B$4,10,1)) -> 0 | E10: =SUM(B10:D10) -> 0
A11: =Lists!A11 -> 0 | B11: =SUMIFS('Hours Log'!$D$5:$D$504,'Hours Log'!$C$5:$C$504,$A11,'Hours Log'!$B$5:$B$504,">="&DATE(Dashboard!$B$4-1,10,1),'Hours Log'!$B$5:$B$504,"<"&DATE(Dashboard!$B$4,10,1)) -> 0 | C11: =SUMIFS('Hours Log'!$E$5:$E$504,'Hours Log'!$C$5:$C$504,$A11,'Hours Log'!$B$5:$B$504,">="&DATE(Dashboard!$B$4-1,10,1),'Hours Log'!$B$5:$B$504,"<"&DATE(Dashboard!$B$4,10,1)) -> 0 | D11: =SUMIFS('Hours Log'!$F$5:$F$504,'Hours Log'!$C$5:$C$504,$A11,'Hours Log'!$B$5:$B$504,">="&DATE(Dashboard!$B$4-1,10,1),'Hours Log'!$B$5:$B$504,"<"&DATE(Dashboard!$B$4,10,1)) -> 0 | E11: =SUM(B11:D11) -> 0
A12: =Lists!A12 -> 0 | B12: =SUMIFS('Hours Log'!$D$5:$D$504,'Hours Log'!$C$5:$C$504,$A12,'Hours Log'!$B$5:$B$504,">="&DATE(Dashboard!$B$4-1,10,1),'Hours Log'!$B$5:$B$504,"<"&DATE(Dashboard!$B$4,10,1)) -> 0 | C12: =SUMIFS('Hours Log'!$E$5:$E$504,'Hours Log'!$C$5:$C$504,$A12,'Hours Log'!$B$5:$B$504,">="&DATE(Dashboard!$B$4-1,10,1),'Hours Log'!$B$5:$B$504,"<"&DATE(Dashboard!$B$4,10,1)) -> 0 | D12: =SUMIFS('Hours Log'!$F$5:$F$504,'Hours Log'!$C$5:$C$504,$A12,'Hours Log'!$B$5:$B$504,">="&DATE(Dashboard!$B$4-1,10,1),'Hours Log'!$B$5:$B$504,"<"&DATE(Dashboard!$B$4,10,1)) -> 0 | E12: =SUM(B12:D12) -> 0
A13: =Lists!A13 -> 0 | B13: =SUMIFS('Hours Log'!$D$5:$D$504,'Hours Log'!$C$5:$C$504,$A13,'Hours Log'!$B$5:$B$504,">="&DATE(Dashboard!$B$4-1,10,1),'Hours Log'!$B$5:$B$504,"<"&DATE(Dashboard!$B$4,10,1)) -> 0 | C13: =SUMIFS('Hours Log'!$E$5:$E$504,'Hours Log'!$C$5:$C$504,$A13,'Hours Log'!$B$5:$B$504,">="&DATE(Dashboard!$B$4-1,10,1),'Hours Log'!$B$5:$B$504,"<"&DATE(Dashboard!$B$4,10,1)) -> 0 | D13: =SUMIFS('Hours Log'!$F$5:$F$504,'Hours Log'!$C$5:$C$504,$A13,'Hours Log'!$B$5:$B$504,">="&DATE(Dashboard!$B$4-1,10,1),'Hours Log'!$B$5:$B$504,"<"&DATE(Dashboard!$B$4,10,1)) -> 0 | E13: =SUM(B13:D13) -> 0
A14: =Lists!A14 -> 0 | B14: =SUMIFS('Hours Log'!$D$5:$D$504,'Hours Log'!$C$5:$C$504,$A14,'Hours Log'!$B$5:$B$504,">="&DATE(Dashboard!$B$4-1,10,1),'Hours Log'!$B$5:$B$504,"<"&DATE(Dashboard!$B$4,10,1)) -> 0 | C14: =SUMIFS('Hours Log'!$E$5:$E$504,'Hours Log'!$C$5:$C$504,$A14,'Hours Log'!$B$5:$B$504,">="&DATE(Dashboard!$B$4-1,10,1),'Hours Log'!$B$5:$B$504,"<"&DATE(Dashboard!$B$4,10,1)) -> 0 | D14: =SUMIFS('Hours Log'!$F$5:$F$504,'Hours Log'!$C$5:$C$504,$A14,'Hours Log'!$B$5:$B$504,">="&DATE(Dashboard!$B$4-1,10,1),'Hours Log'!$B$5:$B$504,"<"&DATE(Dashboard!$B$4,10,1)) -> 0 | E14: =SUM(B14:D14) -> 0
A15: =Lists!A15 -> 0 | B15: =SUMIFS('Hours Log'!$D$5:$D$504,'Hours Log'!$C$5:$C$504,$A15,'Hours Log'!$B$5:$B$504,">="&DATE(Dashboard!$B$4-1,10,1),'Hours Log'!$B$5:$B$504,"<"&DATE(Dashboard!$B$4,10,1)) -> 0 | C15: =SUMIFS('Hours Log'!$E$5:$E$504,'Hours Log'!$C$5:$C$504,$A15,'Hours Log'!$B$5:$B$504,">="&DATE(Dashboard!$B$4-1,10,1),'Hours Log'!$B$5:$B$504,"<"&DATE(Dashboard!$B$4,10,1)) -> 0 | D15: =SUMIFS('Hours Log'!$F$5:$F$504,'Hours Log'!$C$5:$C$504,$A15,'Hours Log'!$B$5:$B$504,">="&DATE(Dashboard!$B$4-1,10,1),'Hours Log'!$B$5:$B$504,"<"&DATE(Dashboard!$B$4,10,1)) -> 0 | E15: =SUM(B15:D15) -> 0
A16: =Lists!A16 -> 0 | B16: =SUMIFS('Hours Log'!$D$5:$D$504,'Hours Log'!$C$5:$C$504,$A16,'Hours Log'!$B$5:$B$504,">="&DATE(Dashboard!$B$4-1,10,1),'Hours Log'!$B$5:$B$504,"<"&DATE(Dashboard!$B$4,10,1)) -> 0 | C16: =SUMIFS('Hours Log'!$E$5:$E$504,'Hours Log'!$C$5:$C$504,$A16,'Hours Log'!$B$5:$B$504,">="&DATE(Dashboard!$B$4-1,10,1),'Hours Log'!$B$5:$B$504,"<"&DATE(Dashboard!$B$4,10,1)) -> 0 | D16: =SUMIFS('Hours Log'!$F$5:$F$504,'Hours Log'!$C$5:$C$504,$A16,'Hours Log'!$B$5:$B$504,">="&DATE(Dashboard!$B$4-1,10,1),'Hours Log'!$B$5:$B$504,"<"&DATE(Dashboard!$B$4,10,1)) -> 0 | E16: =SUM(B16:D16) -> 0
... A44: =Lists!A44 -> 0 | B44: =SUMIFS('Hours Log'!$D$5:$D$504,'Hours Log'!$C$5:$C$504,$A44,'Hours Log'!$B$5:$B$504,">="&DATE(Dashboard!$B$4-1,10,1),'Hours Log'!$B$5:$B$504,"<"&DATE(Dashboard!$B$4,10,1)) -> 0 | C44: =SUMIFS('Hours Log'!$E$5:$E$504,'Hours Log'!$C$5:$C$504,$A44,'Hours Log'!$B$5:$B$504,">="&DATE(Dashboard!$B$4-1,10,1),'Hours Log'!$B$5:$B$504,"<"&DATE(Dashboard!$B$4,10,1)) -> 0 | D44: =SUMIFS('Hours Log'!$F$5:$F$504,'Hours Log'!$C$5:$C$504,$A44,'Hours Log'!$B$5:$B$504,">="&DATE(Dashboard!$B$4-1,10,1),'Hours Log'!$B$5:$B$504,"<"&DATE(Dashboard!$B$4,10,1)) -> 0 | E44: =SUM(B44:D44) -> 0
A45: ALL CLASSES | B45: =SUM(B5:B44) -> 0 | C45: =SUM(C5:C44) -> 0 | D45: =SUM(D5:D44) -> 0 | E45: =SUM(E5:E44) -> 0

Sheet Lists
A1: CLASS REFERENCE LIST
A2: Rename Class 1 - Class 40 below to match your course names; class dropdowns use this list.
A4: CLASSES (EDIT NAMES BELOW)
A5: Class 1
A6: Class 2
A7: Class 3
A8: Class 4
A9: Class 5
A10: Class 6
A11: Class 7
A12: Class 8
A13: Class 9
... A44: Class 40

Sheet Guide
A1: USING THE FEDERAL FISCAL-YEAR TRACKER
A2: 1. On Dashboard!B4, select the fiscal year by ENDING calendar year. FY 2027 = 10/1/2026 - 9/30/2027.
A3: 2. Rename the 40 class placeholders on the Lists sheet. The Hours Log class dropdown uses that list.
A4: 3. On Hours Log, enter a date, class, and any Contact, Production, or Consultation Hours.
A5: 4. The total hours, calendar month/year, and fiscal year calculate automatically for each dated entry.
A6: 5. Dashboard totals and monthly chart follow the selected FY in October-to-September order.
A7: 6. Class Summary breaks down all 40 classes for the selected FY.
A8: 7. Hours Log contains 500 dated entries. Extend formulas and dashboard ranges if your log grows.
A9: 8. Keep one workbook across years and change the selected FY to view prior/future fiscal years.
A10: CONTACT HOURS: Time delivering instruction.
A11: PRODUCTION HOURS: Time developing or preparing instructional materials.
A12: CONSULTATION HOURS: Time providing consultations, support or coaching.
... A14: Original July 2026 tracker concept; revised to federal fiscal-year reporting, October 2026.
